Workbook

Sheet Pivot Table  for Recovery Avail
A3: Sum of Customer_ID | B3: Column Labels
A4: Row Labels | B4: 0 | C4: 0.106 | D4: 1 | E4: 106 | F4: Grand Total
A5: 0 | B5: 430585 | D5: 2441 | F5: 433026
A6: 1 | B6: 14778 | D6: 52696 | F6: 67474
A7: (blank)
A8: Grand Total | B8: 445363 | D8: 55137 | F8: 500500

Sheet Corporate_Data
A1: Customer_ID | B1: Observation_Month | C1: Revenue | D1: Debt | E1: DSCR | F1: Debt_to_Equity | G1: Liquidity_Ratio | H1: Credit_Score | I1: Default_Flag | J1: Recovery_Amount_90D | K1: Default_Flag_Original | L1: Performance_Window_Months | M1: Population | N1: Risk_Score | O1: Recovery_Available | P1: Default Flag Mismatch
A2: 1 | B2: 45108 | C2: 42994 | D2: 9488 | E2: 2.68 | F2: 0.25 | G2: 1.32 | H2: 670 | I2: 0 | K2: 0 | L2: 12 | M2: Development | N2: 0 | O2: =IF(J2="",0,1) -> 0 | P2: =IF(I2=K2,0,1) -> 0
A3: 2 | B3: 45505 | C3: 20175 | D3: 6101 | E3: 0.93 | F3: 0.43 | G3: 1.05 | H3: 674 | I3: 0 | K3: 0 | L3: 18 | M3: Validation | N3: 0.3 | O3: =IF(J3="",0,1) -> 0 | P3: =IF(I3=K3,0,1) -> 0
A4: 3 | B4: 45352 | C4: 55000 | D4: 14744 | E4: 1.81 | F4: 2.58 | G4: 1.44 | H4: 751 | I4: 1 | J4: 2220 | K4: 1 | L4: 12 | M4: Validation | N4: 0.35 | O4: =IF(J4="",0,1) -> 1 | P4: =IF(I4=K4,0,1) -> 0
A5: 4 | B5: 45231 | C5: 12333 | D5: 3874 | E5: 1.04 | F5: 3.32 | G5: 1.87 | H5: 639 | I5: 0 | K5: 0 | L5: 12 | M5: Development | N5: 0.35 | O5: =IF(J5="",0,1) -> 0 | P5: =IF(I5=K5,0,1) -> 0
A6: 5 | B6: 45139 | C6: 34789 | D6: 16751 | E6: 1.86 | F6: 0.84 | G6: 1.63 | H6: 752 | I6: 0 | K6: 0 | L6: 12 | M6: Development | N6: 0 | O6: =IF(J6="",0,1) -> 0 | P6: =IF(I6=K6,0,1) -> 0
A7: 6 | B7: 45536 | C7: 16528 | D7: 12048 | E7: 1.04 | F7: 0.38 | G7: 0.87 | H7: 692 | I7: 0 | K7: 0 | L7: 18 | M7: Validation | N7: 0 | O7: =IF(J7="",0,1) -> 0 | P7: =IF(I7=K7,0,1) -> 0
A8: 7 | B8: 45108 | C8: 23773 | D8: 9641 | E8: 1.32 | F8: 3.92 | G8: 1.76 | H8: 671 | I8: 0 | K8: 0 | L8: 18 | M8: Development | N8: 0.35 | O8: =IF(J8="",0,1) -> 0 | P8: =IF(I8=K8,0,1) -> 0
A9: 8 | B9: 45474 | C9: 37452 | D9: 4375 | E9: 1.39 | F9: 2.76 | G9: 1 | H9: 818 | I9: 0 | K9: 0 | L9: 12 | M9: Validation | N9: 0.35 | O9: =IF(J9="",0,1) -> 0 | P9: =IF(I9=K9,0,1) -> 0
A10: 9 | B10: 45597 | C10: 20759 | D10: 19140 | E10: 2.09 | F10: 1.46 | G10: 1.47 | H10: 622 | I10: 0 | K10: 0 | L10: 6 | M10: Validation | N10: 0 | O10: =IF(J10="",0,1) -> 0 | P10: =IF(I10=K10,0,1) -> 0
A11: 10 | B11: 45231 | C11: 28284 | D11: 9201 | E11: 2.06 | F11: 0.51 | G11: 1.18 | H11: 661 | I11: 0 | K11: 0 | L11: 18 | M11: Development | N11: 0 | O11: =IF(J11="",0,1) -> 0 | P11: =IF(I11=K11,0,1) -> 0
A12: 11 | B12: 45231 | C12: 69849 | D12: 5890 | F12: 0.87 | G12: 1.23 | H12: 612 | I12: 0 | K12: 0 | L12: 18 | M12: Development | N12: 0 | O12: =IF(J12="",0,1) -> 0 | P12: =IF(I12=K12,0,1) -> 0
A13: 12 | B13: 45627 | C13: 24960 | D13: 1789 | E13: 1.58 | F13: 0.81 | G13: 1.77 | H13: 732 | I13: 0 | K13: 0 | L13: 12 | M13: Validation | N13: 0 | O13: =IF(J13="",0,1) -> 0 | P13: =IF(I13=K13,0,1) -> 0
A14: 13 | B14: 45536 | C14: 62517 | D14: 13105 | E14: 1.16 | F14: 1.14 | G14: 0.78 | H14: 773 | I14: 0 | K14: 0 | L14: 18 | M14: Validation | N14: 0.15 | O14: =IF(J14="",0,1) -> 0 | P14: =IF(I14=K14,0,1) -> 0
A15: 14 | B15: 45017 | C15: 17426 | D15: 46193 | E15: 0.86 | F15: 2.5 | G15: 2.42 | H15: 772 | I15: 0 | K15: 0 | L15: 12 | M15: Development | N15: 0.65 | O15: =IF(J15="",0,1) -> 0 | P15: =IF(I15=K15,0,1) -> 0
A16: 15 | B16: 45139 | C16: 51245 | D16: 42740 | E16: 1.43 | F16: 1.67 | G16: 0.35 | H16: 747 | I16: 0 | K16: 0 | L16: 12 | M16: Development | N16: 0.15 | O16: =IF(J16="",0,1) -> 0 | P16: =IF(I16=K16,0,1) -> 0
A17: 16 | B17: 45627 | C17: 92690 | D17: 9701 | E17: 1.38 | F17: 0.43 | G17: 1.02 | H17: 669 | I17: 0 | K17: 0 | L17: 12 | M17: Validation | N17: 0 | O17: =IF(J17="",0,1) -> 0 | P17: =IF(I17=K17,0,1) -> 0
A18: 17 | B18: 44986 | C18: 7284 | D18: 8764 | E18: 2.88 | F18: 2.37 | G18: 1.55 | H18: 660 | I18: 0 | K18: 0 | L18: 12 | M18: Development | N18: 0.35 | O18: =IF(J18="",0,1) -> 0 | P18: =IF(I18=K18,0,1) -> 0
A19: 18 | B19: 45566 | C19: 21634 | D19: 18548 | E19: 1.79 | F19: 1.13 | G19: 1.67 | H19: 588 | I19: 0 | K19: 0 | L19: 18 | M19: Validation | N19: 0.2 | O19: =IF(J19="",0,1) -> 0 | P19: =IF(I19=K19,0,1) -> 0
A20: 19 | B20: 45536 | C20: 52844 | D20: 6642 | E20: 0.79 | F20: 1.46 | G20: 1.29 | H20: 792 | I20: 0 | K20: 0 | L20: 6 | M20: Validation | N20: 0.3 | O20: =IF(J20="",0,1) -> 0 | P20: =IF(I20=K20,0,1) -> 0
A21: 20 | B21: 44958 | C21: 31825 | D21: 16502 | E21: 1.24 | F21: 2.53 | G21: 1.32 | H21: 706 | I21: 0 | K21: 0 | L21: 18 | M21: Development | N21: 0.35 | O21: =IF(J21="",0,1) -> 0 | P21: =IF(I21=K21,0,1) -> 0
A22: 21 | B22: 45627 | C22: 46224 | D22: 22840 | E22: 2.11 | F22: 0.42 | G22: 1.58 | H22: 653 | I22: 0 | K22: 0 | L22: 12 | M22: Validation | N22: 0 | O22: =IF(J22="",0,1) -> 0 | P22: =IF(I22=K22,0,1) -> 0
A23: 22 | B23: 45261 | C23: 24524 | D23: 31535 | E23: 2.7 | F23: 0.88 | G23: 1.22 | H23: 753 | I23: 0 | K23: 0 | L23: 6 | M23: Development | N23: 0 | O23: =IF(J23="",0,1) -> 0 | P23: =IF(I23=K23,0,1) -> 0
A24: 23 | B24: 45078 | C24: 38418 | D24: 12455 | E24: 0.68 | F24: 0.62 | G24: 2.12 | H24: 626 | I24: 0 | K24: 0 | L24: 12 | M24: Development | N24: 0.3 | O24: =IF(J24="",0,1) -> 0 | P24: =IF(I24=K24,0,1) -> 0
A25: 24 | B25: 44958 | C25: 32821 | D25: 11585 | E25: 0.52 | F25: 0.3 | G25: 1.81 | H25: 702 | I25: 0 | K25: 0 | L25: 12 | M25: Development | N25: 0.3 | O25: =IF(J25="",0,1) -> 0 | P25: =IF(I25=K25,0,1) -> 0
A26: 25 | B26: 45536 | C26: 77579 | D26: 7226 | E26: 2.58 | F26: 1.15 | G26: 1.83 | I26: 0 | K26: 0 | L26: 18 | M26: Validation | N26: 0 | O26: =IF(J26="",0,1) -> 0 | P26: =IF(I26=K26,0,1) -> 0
A27: 26 | B27: 44927 | C27: 42846 | D27: 7489 | E27: 1.76 | F27: 5.25 | G27: 0.82 | H27: 715 | I27: 0 | K27: 0 | L27: 18 | M27: Development | N27: 0.35 | O27: =IF(J27="",0,1) -> 0 | P27: =IF(I27=K27,0,1) -> 0
A28: 27 | B28: 45261 | C28: 45227 | D28: 11401 | E28: 1.07 | F28: 0.25 | G28: 1.31 | H28: 677 | I28: 0 | K28: 0 | L28: 6 | M28: Development | N28: 0 | O28: =IF(J28="",0,1) -> 0 | P28: =IF(I28=K28,0,1) -> 0
A29: 28 | B29: 45566 | C29: 27786 | D29: 17277 | E29: 1.84 | F29: 0.88 | G29: 1.18 | H29: 600 | I29: 0 | K29: 0 | L29: 6 | M29: Validation | N29: 0 | O29: =IF(J29="",0,1) -> 0 | P29: =IF(I29=K29,0,1) -> 0
A30: 29 | B30: 45261 | C30: 26451 | D30: 25324 | E30: 0.2 | F30: 1.42 | G30: 0.8 | H30: 684 | I30: 0 | K30: 0 | L30: 18 | M30: Development | N30: 0.3 | O30: =IF(J30="",0,1) -> 0 | P30: =IF(I30=K30,0,1) -> 0
A31: 30 | B31: 45413 | C31: 27415 | D31: 7614 | E31: 1.55 | F31: 0.99 | G31: 1.55 | H31: 738 | I31: 0 | K31: 0 | L31: 12 | M31: Validation | N31: 0 | O31: =IF(J31="",0,1) -> 0 | P31: =IF(I31=K31,0,1) -> 0
A32: 31 | B32: 45200 | C32: 46929 | D32: 37983 | E32: 1.73 | F32: 0.84 | G32: 1.05 | H32: 678 | I32: 0 | K32: 0 | L32: 12 | M32: Development | N32: 0 | O32: =IF(J32="",0,1) -> 0 | P32: =IF(I32=K32,0,1) -> 0
A33: 32 | B33: 45383 | C33: 27622 | D33: 11050 | E33: 2.06 | F33: 0.36 | G33: 1.71 | H33: 723 | I33: 0 | K33: 0 | L33: 6 | M33: Validation | N33: 0 | O33: =IF(J33="",0,1) -> 0 | P33: =IF(I33=K33,0,1) -> 0
A34: 33 | B34: 45352 | C34: 43842 | D34: 13161 | E34: 0.99 | F34: 1.06 | G34: 0.76 | H34: 622 | I34: 0 | K34: 0 | L34: 12 | M34: Validation | N34: 0.45 | O34: =IF(J34="",0,1) -> 0 | P34: =IF(I34=K34,0,1) -> 0
A35: 34 | B35: 45352 | C35: 139946 | D35: 7918 | E35: 1.6 | F35: 0.53 | G35: 2.3 | H35: 679 | I35: 0 | K35: 0 | L35: 18 | M35: Validation | N35: 0 | O35: =IF(J35="",0,1) -> 0 | P35: =IF(I35=K35,0,1) -> 0
A36: 35 | B36: 45474 | C36: 63974 | D36: 2448 | E36: 1.04 | F36: 0.2 | G36: 0.86 | H36: 646 | I36: 1 | K36: 0 | L36: 12 | M36: Validation | N36: 0 | O36: =IF(J36="",0,1) -> 0 | P36: =IF(I36=K36,0,1) -> 1
A37: 36 | B37: 45261 | C37: 29380 | D37: 24806 | E37: 1.69 | F37: 2.09 | G37: 1.47 | H37: 721 | I37: 0 | K37: 0 | L37: 6 | M37: Development | N37: 0.35 | O37: =IF(J37="",0,1) -> 0 | P37: =IF(I37=K37,0,1) -> 0
A38: 37 | B38: 45597 | C38: 79284 | D38: 22377 | E38: 1.06 | F38: 1.77 | G38: 1.79 | H38: 682 | I38: 0 | K38: 0 | L38: 12 | M38: Validation | N38: 0 | O38: =IF(J38="",0,1) -> 0 | P38: =IF(I38=K38,0,1) -> 0
... A40: 39 | B40: 44986 | C40: 9655 | D40: 14001 | E40: 1 | F40: 1.06 | G40: 1.82 | H40: 740 | I40: 0 | K40: 0 | L40: 12 | M40: Development | N40: 0 | O40: =IF(J40="",0,1) -> 0 | P40: =IF(I40=K40,0,1) -> 0
A41: 40 | B41: 45047 | C41: 18859 | D41: 19171 | E41: 1.91 | F41: 1.92 | G41: 0.67 | H41: 718 | I41: 1 | J41: 26504 | K41: 1 | L41: 12 | M41: Development | N41: 0.15 | O41: =IF(J41="",0,1) -> 1 | P41: =IF(I41=K41,0,1) -> 0
...

Sheet Missing_Value_Check
A1: Variable | B1: Missing_Count | C1: Missing_% | E1: Missing Values | F1: Missing % | H1: Variable | I1: Missing Value | J1: Missing %
A2: Customer_ID | B2: 0 | C2: 0 | E2: =COUNTBLANK(Corporate_Data!C2:C97) -> 0 | H2: Revenue | I2: =COUNTBLANK(Corporate_Data!C2:C1001) -> 25 | J2: =I2/COUNT(Corporate_Data!A2:A1001) -> 0.025
A3: Observation_Month | B3: 0 | C3: 0 | H3: DSCR | I3: =COUNTBLANK(Corporate_Data!E2:E1001) -> 30 | J3: =I3/COUNT(Corporate_Data!A2:A1001) -> 0.03
A4: Revenue | B4: 25 | C4: 0.025 | H4: Credit Score | I4: =COUNTBLANK(Corporate_Data!H2:H1001) -> 20 | J4: =I4/COUNT(Corporate_Data!A2:A1001) -> 0.02
A5: Debt | B5: 0 | C5: 0
A6: DSCR | B6: 30 | C6: 0.03
A7: Debt_to_Equity | B7: 0 | C7: 0
A8: Liquidity_Ratio | B8: 0 | C8: 0
A9: Credit_Score | B9: 20 | C9: 0.02
A10: Default_Flag | B10: 0 | C10: 0
A11: Recovery_Amount_90D | B11: 894 | C11: 0.894
A12: Default_Flag_Original | B12: 0 | C12: 0
A13: Performance_Window_Months | B13: 0 | C13: 0
A14: Population | B14: 0 | C14: 0
A15: Risk_Score | B15: 0 | C15: 0

Sheet Default_Flag_Check
A1: Customer_ID | B1: Original_Default_Flag | C1: Current_Default_Flag | D1: Mismatch
A2: 1 | B2: 0 | C2: 0 | D2: 0
A3: 2 | B3: 0 | C3: 0 | D3: 0
A4: 3 | B4: 1 | C4: 1 | D4: 0
A5: 4 | B5: 0 | C5: 0 | D5: 0
A6: 5 | B6: 0 | C6: 0 | D6: 0
A7: 6 | B7: 0 | C7: 0 | D7: 0
A8: 7 | B8: 0 | C8: 0 | D8: 0
A9: 8 | B9: 0 | C9: 0 | D9: 0
A10: 9 | B10: 0 | C10: 0 | D10: 0
A11: 10 | B11: 0 | C11: 0 | D11: 0
A12: 11 | B12: 0 | C12: 0 | D12: 0
A13: 12 | B13: 0 | C13: 0 | D13: 0
... A1001: 1000 | B1001: 0 | C1001: 0 | D1001: 0

Sheet Population_Shift
A1: Population | B1: Customers | C1: Avg_Revenue | D1: Avg_Debt | E1: Avg_DSCR | F1: Avg_Credit_Score | G1: Default_Rate
A2: Development | B2: 495 | C2: =AVERAGEIF(Corporate_Data!M2:M1001,"Development",Corporate_Data!C2:C1001) -> 46179.563 | D2: =AVERAGEIF(Corporate_Data!M2:M1001,"Development",Corporate_Data!D2:D1001) -> 17297.059 | E2: =AVERAGEIF(Corporate_Data!M2:M1001,"Development",Corporate_Data!E2:E1001) -> 1.5309034 | F2: =AVERAGEIF(Corporate_Data!M2:M1001,"Development",Corporate_Data!F2:F1001) -> 1.1149091 | G2: 0.13939394
A3: Validation | B3: 505 | C3: =AVERAGEIF(Corporate_Data!M2:M1001,"Validation",Corporate_Data!C2:C1001) -> 48072.939 | D3: =AVERAGEIF(Corporate_Data!M2:M1001,"Validation",Corporate_Data!D2:D1001) -> 16705.638 | E3: =AVERAGEIF(Corporate_Data!M2:M1001,"Validation",Corporate_Data!E2:E1001) -> 1.5665992 | F3: =AVERAGEIF(Corporate_Data!M2:M1001,"Validation",Corporate_Data!F2:F1001) -> 1.0994653 | G3: 0.12673267
A5: A | B5: B | C5: C | D5: D | E5: E | F5: F
A6: Credit Score Band | B6: Development Count | C6: Validation Count | D6: Dev % | E6: Val % | F6: PSI
A7: <600 | B7: =COUNTIFS(Corporate_Data!H:H,"<600",Corporate_Data!M:M,"Development") -> 34 | C7: =COUNTIFS(Corporate_Data!H:H,"<600",Corporate_Data!M:M,"Validation") -> 47 | D7: =B7/$B$12 -> 0.070393375 | E7: =C7/$C$12 -> 0.094567404 | F7: =(E7-D7)*LN(E7/D7) -> 0.0071365049
A8: 600–649 | B8: =COUNTIFS(Corporate_Data!$H$2:$H$1001,">=600",Corporate_Data!$H$2:$H$1001,"<650",Corporate_Data!$M$2:$M$1001,"Development") -> 112 | C8: =COUNTIFS(Corporate_Data!$H$2:$H$1001,">=600",Corporate_Data!$H$2:$H$1001,"<650",Corporate_Data!$M$2:$M$1001,"Validation") -> 105 | D8: =B8/$B$12 -> 0.23188406 | E8: =C8/$C$12 -> 0.21126761 | F8: =(E8-D8)*LN(E8/D8) -> 0.0019196369
A9: 650–699 | B9: =COUNTIFS(Corporate_Data!$H$2:$H$1001,">=650",Corporate_Data!$H$2:$H$1001,"<700",Corporate_Data!$M$2:$M$1001,"Development") -> 169 | C9: =COUNTIFS(Corporate_Data!$H$2:$H$1001,">=650",Corporate_Data!$H$2:$H$1001,"<700",Corporate_Data!$M$2:$M$1001,"Validation") -> 174 | D9: =B9/$B$12 -> 0.34989648 | E9: =C9/$C$12 -> 0.3501006 | F9: =(E9-D9)*LN(E9/D9) -> 1.1904712e-07
A10: 700–749 | B10: =COUNTIFS(Corporate_Data!$H$2:$H$1001,">=700",Corporate_Data!$H$2:$H$1001,"<750",Corporate_Data!$M$2:$M$1001,"Development") -> 117 | C10: =COUNTIFS(Corporate_Data!$H$2:$H$1001,">=700",Corporate_Data!$H$2:$H$1001,"<750",Corporate_Data!$M$2:$M$1001,"Validation") -> 119 | D10: =B10/$B$12 -> 0.24223602 | E10: =C10/$C$12 -> 0.23943662 | F10: =(E10-D10)*LN(E10/D10) -> 3.2539765e-05
A11: ≥750 | B11: =COUNTIFS(Corporate_Data!$H$2:$H$1001,">=750",Corporate_Data!$M$2:$M$1001,"Development") -> 51 | C11: =COUNTIFS(Corporate_Data!$H$2:$H$1001,">=750",Corporate_Data!$M$2:$M$1001,"Validation") -> 52 | D11: =B11/$B$12 -> 0.10559006 | E11: =C11/$C$12 -> 0.10462777 | F11: =(E11-D11)*LN(E11/D11) -> 8.8100912e-06
B12: =SUM(B7:B11) -> 483 | C12: =SUM(C7:C11) -> 497

Sheet Window_Check
A1: Performance_Window_Months | B1: Customer_Count | C1: Share
A2: 6 | B2: =COUNTIF(Corporate_Data!L2:L1001,6) -> 195 | C2: =B2/B5 -> 0.195
A3: 12 | B3: =COUNTIF(Corporate_Data!L2:L1001,12) -> 611 | C3: =B3/B5 -> 0.611
A4: 18 | B4: =COUNTIF(Corporate_Data!L2:L1001,18) -> 194 | C4: =B4/B5 -> 0.194
B5: =SUM(B2:B4) -> 1000
B6: This means (1000-611) 389 customers are not using the 12 month window
